#VRML_SIM R2023b utf8

EXTERNPROTO "https://raw.githubusercontent.com/cyberbotics/webots/R2023b/projects/objects/backgrounds/protos/TexturedBackground.proto"
EXTERNPROTO "https://raw.githubusercontent.com/cyberbotics/webots/R2023b/projects/objects/backgrounds/protos/TexturedBackgroundLight.proto"
EXTERNPROTO "https://raw.githubusercontent.com/cyberbotics/webots/R2023b/projects/objects/floors/protos/RectangleArena.proto"

WorldInfo {
}
Viewpoint {
  orientation -0.5773502691896258 0.5773502691896258 0.5773502691896258 2.0944
  position 0.030941408839431122 6.83720924495335e-06 4.144900355007915
}
TexturedBackground {
}
TexturedBackgroundLight {
}
RectangleArena {
  floorSize 1.5 1.5
}
DEF robot Robot {
  translation 0 0 0.05
  rotation 0.9998722047246247 0.015986638785114027 3.9993404147973756e-05 0.0012890145081638712
  children [
    DEF ds0 DistanceSensor {
      translation 0.09 -0.03 0
      rotation 0 0 1 -0.45
      children [
        DEF distance_sensor Shape {
          appearance PBRAppearance {
            baseColor 0.5 0.5 0.5
            metalness 0
          }
          geometry Box {
            size 0.01 0.01 0.01
          }
        }
      ]
      name "ds0"
      boundingObject USE distance_sensor
      physics Physics {
      }
      lookupTable [
        0 1000 0
        0.05 1000 0
        0.15 0 0
      ]
      numberOfRays 2
      aperture 1
    }
    DEF ds1 DistanceSensor {
      translation 0.09 0.03 0
      rotation 0 0 1 0.45
      children [
        DEF distance_sensor Shape {
          appearance PBRAppearance {
            baseColor 0.5 0.5 0.5
            metalness 0
          }
          geometry Box {
            size 0.01 0.01 0.01
          }
        }
      ]
      name "ds1"
      boundingObject USE distance_sensor
      physics Physics {
      }
      lookupTable [
        0 1000 0
        0.05 1000 0
        0.15 0 0
      ]
      numberOfRays 2
      aperture 1
    }
    DEF caster BallJoint {
      jointParameters BallJointParameters {
        anchor 0.06 0 -0.0375
      }
      jointParameters2 JointParameters {
      }
      jointParameters3 JointParameters {
        axis 0 1 0
      }
      endPoint DEF caster Solid {
        translation 0.06 0 -0.0375
        children [
          DEF caster Shape {
            appearance PBRAppearance {
              baseColor 0 0 0
              metalness 0
            }
            geometry Sphere {
              radius 0.0125
            }
          }
        ]
        name "caster"
        boundingObject USE caster
        physics Physics {
        }
      }
    }
    DEF body Shape {
      appearance PBRAppearance {
        baseColor 1 0 0
        metalness 0
      }
      geometry Box {
        size 0.1 0.1 0.05
      }
    }
    DEF Front_frame Solid {
      translation 0.05 0 0
      children [
        DEF front_frame Shape {
          appearance PBRAppearance {
            baseColor 1 0 0
            metalness 0
          }
          geometry Cylinder {
            height 0.05
            radius 0.05
          }
        }
      ]
      boundingObject USE front_frame
      physics Physics {
      }
    }
    DEF wheel1 HingeJoint {
      jointParameters HingeJointParameters {
        axis 0 1 0
        anchor 0 0.06 -0.02
      }
      device [
        DEF encoder1 PositionSensor {
          name "encoder1"
        }
        DEF motor1 RotationalMotor {
          name "motor1"
        }
      ]
      endPoint DEF wheel1 Solid {
        translation 0 0.06 -0.02
        rotation 1 0 0 1.569999999999999
        children [
          DEF wheel Shape {
            appearance PBRAppearance {
              baseColor 0 0 0
              metalness 0
            }
            geometry Cylinder {
              height 0.02
              radius 0.03
            }
          }
        ]
        name "wheel1"
        boundingObject USE wheel
        physics Physics {
        }
      }
    }
    DEF wheel2 HingeJoint {
      jointParameters HingeJointParameters {
        axis 0 1 0
        anchor 0 -0.06 -0.02
      }
      device [
        DEF encoder2 PositionSensor {
          name "encoder2"
        }
        DEF motor2 RotationalMotor {
          name "motor2"
        }
      ]
      endPoint DEF wheel2 Solid {
        translation 0 -0.06 -0.02
        rotation 1 0 0 1.5699999999999987
        children [
          DEF wheel Shape {
            appearance PBRAppearance {
              baseColor 0 0 0
              metalness 0
            }
            geometry Cylinder {
              height 0.02
              radius 0.03
            }
          }
        ]
        name "wheel2"
        boundingObject USE wheel
        physics Physics {
        }
      }
    }
  ]
  boundingObject USE body
  physics Physics {
  }
  controller "<extern>"
}
