<?xml version="1.0" ?>
<sdf version="1.8">
    <world name="diff_drive_world">

        <scene>
            <grid>false</grid>
        </scene>

        <physics name="1ms" type="ignored">
            <max_step_size>0.001</max_step_size>
            <real_time_factor>1.0</real_time_factor>
        </physics>

        <!-- PLUGINS -->
        <plugin
            filename="gz-sim-physics-system"
            name="gz::sim::systems::Physics">
        </plugin>
        <plugin
            filename="gz-sim-user-commands-system"
            name="gz::sim::systems::UserCommands">
        </plugin>
        <plugin
            filename="gz-sim-scene-broadcaster-system"
            name="gz::sim::systems::SceneBroadcaster">
        </plugin>
        <plugin
            filename="gz-sim-sensors-system"
            name="gz::sim::systems::Sensors">
            <render_engine>ogre2</render_engine>
        </plugin>

        <light type="directional" name="sun">
            <cast_shadows>true</cast_shadows>
            <pose>0 0 10 0 0 0</pose>
            <diffuse>0.8 0.8 0.8 1</diffuse>
            <specular>0.2 0.2 0.2 1</specular>
            <attenuation>
                <range>1000</range>
                <constant>0.9</constant>
                <linear>0.01</linear>
                <quadratic>0.001</quadratic>
            </attenuation>
            <direction>-0.5 0.1 -0.9</direction>
        </light>

        <!-- MODELS -->
        <model name="arena">
            <static>true</static>
            <link name="floor">
                <collision name="collision">
                    <geometry>
                        <plane>
                            <normal>0 0 1</normal>
                        </plane>
                    </geometry>
                </collision>
                <visual name="visual">
                    <geometry>
                        <plane>
                            <normal>0 0 1</normal>
                            <size>5 5</size>
                        </plane>
                    </geometry>
                    <material>
                        <ambient>0.8 0.8 0.8 1</ambient>
                        <diffuse>0.8 0.8 0.8 1</diffuse>
                        <specular>0.8 0.8 0.8 1</specular>
                    </material>
                </visual>
            </link>

            <link name="w1">
                <pose relative_to="floor">0 2.5 0.25 0 0 0</pose>
                <collision name="collision">
                    <geometry>
                        <box>
                            <size>5 0.02 0.5</size>
                        </box>
                    </geometry>
                </collision>
                <visual name="visual">
                    <geometry>
                        <box>
                            <size>5 0.02 0.5</size>
                        </box>
                    </geometry>
                    <material>
                        <ambient>0.8 0.8 0.8 1</ambient>
                        <diffuse>0.8 0.8 0.8 1</diffuse>
                        <specular>0.8 0.8 0.8 1</specular>
                    </material>
                </visual>
            </link>
            <link name="w2">
                <pose relative_to="floor">0 -2.5 0.25 0 0 0</pose>
                <collision name="collision">
                    <geometry>
                        <box>
                            <size>5 0.02 0.5</size>
                        </box>
                    </geometry>
                </collision>
                <visual name="visual">
                    <geometry>
                        <box>
                            <size>5 0.02 0.5</size>
                        </box>
                    </geometry>
                    <material>
                        <ambient>0.8 0.8 0.8 1</ambient>
                        <diffuse>0.8 0.8 0.8 1</diffuse>
                        <specular>0.8 0.8 0.8 1</specular>
                    </material>
                </visual>
            </link>
            <link name="w3">
                <pose relative_to="floor">2.5 0 0.25 0 0 0</pose>
                <collision name="collision">
                    <geometry>
                        <box>
                            <size>0.02 5 0.5</size>
                        </box>
                    </geometry>
                </collision>
                <visual name="visual">
                    <geometry>
                        <box>
                            <size>0.02 5 0.5</size>
                        </box>
                    </geometry>
                    <material>
                        <ambient>0.8 0.8 0.8 1</ambient>
                        <diffuse>0.8 0.8 0.8 1</diffuse>
                        <specular>0.8 0.8 0.8 1</specular>
                    </material>
                </visual>
            </link>
            <link name="w4">
                <pose relative_to="floor">-2.5 0 0.25 0 0 0</pose>
                <collision name="collision">
                    <geometry>
                        <box>
                            <size>0.02 5 0.5</size>
                        </box>
                    </geometry>
                </collision>
                <visual name="visual">
                    <geometry>
                        <box>
                            <size>0.02 5 0.5</size>
                        </box>
                    </geometry>
                    <material>
                        <ambient>0.8 0.8 0.8 1</ambient>
                        <diffuse>0.8 0.8 0.8 1</diffuse>
                        <specular>0.8 0.8 0.8 1</specular>
                    </material>
                </visual>
            </link>
        </model>

        <!-- ############################################################################# -->
        <model name='diff_drive' canonical_link='base_link'>

            <pose relative_to='world'>0 0 0 0 0 0</pose> 

            <!-- Robot body -->
            <link name="base_link">
                <pose relative_to='__model__'>0 0 0.05 0 0 0</pose>
                <inertial>
                    <mass>1.14395</mass>
                    <inertia>
                        <ixx>0.095329</ixx>
                        <ixy>0</ixy>
                        <ixz>0</ixz>
                        <iyy>0.381317</iyy>
                        <iyz>0</iyz>
                        <izz>0.476646</izz>
                    </inertia>
                </inertial>
                <visual name="visual">
                    <geometry>
                        <box>
                            <size>0.1 0.1 0.05</size>
                        </box>
                    </geometry>
                    <material>
                        <ambient>1.0 0.0 0.0 1</ambient>
                        <diffuse>1.0 0.0 0.0 1</diffuse>
                        <specular>1.0 0.0 0.0 1</specular>
                    </material>
                </visual>
                <collision name="collision">
                    <geometry>
                        <box>
                            <size>0.1 0.1 0.05</size>
                        </box>
                    </geometry>
                </collision>
            </link>

            <joint name="base_link_to_front_frame" type="fixed">
                <pose relative_to="base_link">0.05 0 0 0 0 0</pose>
                <parent>base_link</parent>
                <child>front_frame</child>
            </joint>

            <link name="front_frame">
                <pose relative_to="base_link_to_front_frame"/>
                <inertial> 
                    <mass>1.14395</mass>
                    <inertia>
                        <ixx>0.095329</ixx>
                        <ixy>0</ixy>
                        <ixz>0</ixz>
                        <iyy>0.381317</iyy>
                        <iyz>0</iyz>
                        <izz>0.476646</izz>
                    </inertia>
                </inertial>
                <visual name="visual">
                    <geometry>
                        <cylinder>
                            <radius>0.05</radius>
                            <length>0.05</length>
                        </cylinder>
                    </geometry>
                    <material>
                        <ambient>1.0 0.0 0.0 1</ambient>
                        <diffuse>1.0 0.0 0.0 1</diffuse>
                        <specular>1.0 0.0 0.0 1</specular>
                    </material>
                </visual>
                <collision name="collision">
                    <geometry>
                        <cylinder>
                            <radius>0.05</radius>
                            <length>0.05</length>
                        </cylinder>
                    </geometry>
                </collision>
            </link>

            <joint name="base_link_to_lidar" type="fixed">
                <pose relative_to="base_link">0 0 0.0375 0 0 0</pose>
                <parent>base_link</parent>
                <child>lidar</child>
            </joint>

            <link name="lidar">
                <pose relative_to="base_link_to_lidar"/>
                <inertial>
                    <mass>0.5</mass>
                    <inertia>
                        <ixx>0.000104</ixx>
                        <ixy>0</ixy>
                        <ixz>0</ixz>
                        <iyy>0.000104</iyy>
                        <iyz>0</iyz>
                        <izz>0.000156</izz>
                    </inertia>
                </inertial>
                <visual name="visual">
                    <geometry>
                        <cylinder>
                            <radius>0.025</radius>
                            <length>0.025</length>
                        </cylinder>
                    </geometry>
                    <material>
                        <ambient>0.4 0.4 0.4 1</ambient>
                        <diffuse>0.4 0.4 0.4 1</diffuse>
                        <specular>0.4 0.4 0.4 1</specular>
                    </material>
                </visual>
                <collision name="collision">
                    <geometry>
                        <cylinder>
                            <radius>0.025</radius>
                            <length>0.025</length>
                        </cylinder>
                    </geometry>
                </collision>

                <sensor name='gpu_lidar' type='gpu_lidar'>"
                    <pose relative_to='lidar'>0 0 0 0 0 0</pose>
                    <ignition_frame_id>diff_drive/lidar</ignition_frame_id>
                    <topic>scan</topic>
                    <update_rate>10</update_rate>
                    <ray>
                        <scan>
                            <horizontal>
                                <samples>640</samples>
                                <resolution>1</resolution>
                                <min_angle>-3.14</min_angle>
                                <max_angle>3.14</max_angle>
                            </horizontal>
                            <vertical>
                                <samples>1</samples>
                                <resolution>0.01</resolution>
                                <min_angle>0</min_angle>
                                <max_angle>0</max_angle>
                            </vertical>
                        </scan>
                        <range>
                            <min>0.08</min>
                            <max>10.0</max>
                            <resolution>0.01</resolution>
                        </range>
                    </ray>
                    <always_on>1</always_on>
                    <visualize>true</visualize>
                </sensor>
            </link>

            <!-- Wheel 1 -->
            <joint name="motor1" type="revolute">
                <pose relative_to='wheel1'/>
                <parent>base_link</parent>
                <child>wheel1</child>
                <axis>
                    <xyz expressed_in='__model__'>0 1 0</xyz> <!--can be descired to any frame or even arbitrary frames-->
                    <limit>
                        <lower>-1.79769e+308</lower>    <!--negative infinity-->
                        <upper>1.79769e+308</upper>     <!--positive infinity-->
                    </limit>
                </axis>
            </joint>

            <link name="wheel1">
                <pose relative_to="base_link">0 0.06 -0.02 1.5707 0 0</pose>
                <inertial>
                    <mass>0.5</mass>
                    <inertia>
                        <ixx>0.000129</ixx>
                        <ixy>0</ixy>
                        <ixz>0</ixz>
                        <iyy>0.000129</iyy>
                        <iyz>0</iyz>
                        <izz>0.000225</izz>
                    </inertia>
                </inertial>
                <visual name="visual">
                    <geometry>
                        <cylinder>
                            <radius>0.03</radius>
                            <length>0.02</length>
                        </cylinder>
                    </geometry>
                    <material>
                        <ambient>0.0 0.0 0.0 1</ambient>
                        <diffuse>0.0 0.0 0.0 1</diffuse>
                        <specular>0.0 0.0 0.0 1</specular>
                    </material>
                </visual>
                <collision name="collision">
                    <geometry>
                        <cylinder>
                            <radius>0.03</radius>
                            <length>0.02</length>
                        </cylinder>
                    </geometry>
                </collision>
            </link>

            <!-- Wheel 2 -->
            <joint name="motor2" type="revolute">
                <pose relative_to='wheel2'/>
                <parent>base_link</parent>
                <child>wheel2</child>
                <axis>
                    <xyz expressed_in='__model__'>0 1 0</xyz> <!--can be descired to any frame or even arbitrary frames-->
                    <limit>
                        <lower>-1.79769e+308</lower>    <!--negative infinity-->
                        <upper>1.79769e+308</upper>     <!--positive infinity-->
                    </limit>
                </axis>
            </joint>

            <link name="wheel2">
                <pose relative_to="base_link">0 -0.06 -0.02 1.5707 0 0</pose>
                <inertial>
                    <mass>0.5</mass>
                    <inertia>
                        <ixx>0.000129</ixx>
                        <ixy>0</ixy>
                        <ixz>0</ixz>
                        <iyy>0.000129</iyy>
                        <iyz>0</iyz>
                        <izz>0.000225</izz>
                    </inertia>
                </inertial>
                <visual name="visual">
                    <geometry>
                        <cylinder>
                            <radius>0.03</radius>
                            <length>0.02</length>
                        </cylinder>
                    </geometry>
                    <material>
                        <ambient>0.0 0.0 0.0 1</ambient>
                        <diffuse>0.0 0.0 0.0 1</diffuse>
                        <specular>0.0 0.0 0.0 1</specular>
                    </material>
                </visual>
                <collision name="collision">
                    <geometry>
                        <cylinder>
                            <radius>0.03</radius>
                            <length>0.02</length>
                        </cylinder>
                    </geometry>
                </collision>
            </link>

            <!-- Caster Wheel -->
            <joint name="base_link_to_caster" type="ball">
                <pose relative_to='caster'/>
                <parent>base_link</parent>
                <child>caster</child>
            </joint>

            <link name="caster">
                <pose relative_to="base_link">0.06 0 -0.0375 0 0 0</pose>
                <inertial>
                    <mass>0.5</mass>
                    <inertia>
                        <ixx>0.000031</ixx>
                        <ixy>0</ixy>
                        <ixz>0</ixz>
                        <iyy>0.000031</iyy>
                        <iyz>0</iyz>
                        <izz>0.000031</izz>
                    </inertia>
                </inertial>
                <visual name="visual">
                    <geometry>
                        <sphere>
                            <radius>0.0125</radius>
                        </sphere>
                    </geometry>
                    <material>
                        <ambient>0.0 0.0 0.0 1</ambient>
                        <diffuse>0.0 0.0 0.0 1</diffuse>
                        <specular>0.0 0.0 0.0 1</specular>
                    </material>
                </visual>
                <collision name="collision">
                    <geometry>
                        <sphere>
                            <radius>0.0125</radius>
                        </sphere>
                    </geometry>
                </collision>
            </link>

            <plugin
                filename="gz-sim-diff-drive-system"
                name="gz::sim::systems::DiffDrive">
                <left_joint>motor1</left_joint>
                <right_joint>motor2</right_joint>
                <wheel_separation>0.1</wheel_separation>
                <wheel_radius>0.03</wheel_radius>
                <odom_publish_frequency>1</odom_publish_frequency>
                <topic>cmd_vel</topic>
            </plugin>

            <plugin
                filename="gz-sim-joint-state-publisher-system"
                name="gz::sim::systems::JointStatePublisher">
            </plugin>

            <plugin
                filename="ignition-gazebo-pose-publisher-system"
                name="ignition::gazebo::systems::PosePublisher">
                <publish_link_pose>true</publish_link_pose>

                <use_pose_vector_msg>true</use_pose_vector_msg>
            </plugin>

        </model>

        <!-- #################################################################### -->

        <!-- Obstacles -->
        <model name="box1">
            <pose>0 -1 0.25 0 0 0</pose>
            <link name="box_link">
                <inertial>
                <inertia>
                    <ixx>1</ixx>
                    <ixy>0</ixy>
                    <ixz>0</ixz>
                    <iyy>1</iyy>
                    <iyz>0</iyz>
                    <izz>1</izz>
                </inertia>
                <mass>1.0</mass>
                </inertial>
                <collision name="box_collision">
                    <geometry>
                        <box>
                            <size>0.5 0.5 0.5</size>
                        </box>
                    </geometry>
                </collision>
                <visual name="box_visual">
                    <geometry>
                        <box>
                            <size>0.5 0.5 0.5</size>
                        </box>
                    </geometry>
                <material>
                    <ambient>1 0 0 1</ambient>
                    <diffuse>1 0 0 1</diffuse>
                    <specular>1 0 0 1</specular>
                </material>
                </visual>
            </link>
        </model>

        <model name="box2">
            <pose>0 1 0.25 0 0 0</pose>
            <link name="box_link">
                <inertial>
                <inertia>
                    <ixx>1</ixx>
                    <ixy>0</ixy>
                    <ixz>0</ixz>
                    <iyy>1</iyy>
                    <iyz>0</iyz>
                    <izz>1</izz>
                </inertia>
                <mass>1.0</mass>
                </inertial>
                <collision name="box_collision">
                    <geometry>
                        <box>
                            <size>0.5 0.5 0.5</size>
                        </box>
                    </geometry>
                </collision>
                <visual name="box_visual">
                    <geometry>
                        <box>
                            <size>0.5 0.5 0.5</size>
                        </box>
                    </geometry>
                <material>
                    <ambient>1 0 0 1</ambient>
                    <diffuse>1 0 0 1</diffuse>
                    <specular>1 0 0 1</specular>
                </material>
                </visual>
            </link>
        </model>

        <model name="box3">
            <pose>-1 0 0.25 0 0 0</pose>
            <link name="box_link">
                <inertial>
                <inertia>
                    <ixx>1</ixx>
                    <ixy>0</ixy>
                    <ixz>0</ixz>
                    <iyy>1</iyy>
                    <iyz>0</iyz>
                    <izz>1</izz>
                </inertia>
                <mass>1.0</mass>
                </inertial>
                <collision name="box_collision">
                    <geometry>
                        <box>
                            <size>0.5 0.5 0.5</size>
                        </box>
                    </geometry>
                </collision>
                <visual name="box_visual">
                    <geometry>
                        <box>
                            <size>0.5 0.5 0.5</size>
                        </box>
                    </geometry>
                <material>
                    <ambient>1 0 0 1</ambient>
                    <diffuse>1 0 0 1</diffuse>
                    <specular>1 0 0 1</specular>
                </material>
                </visual>
            </link>
        </model>

        <model name="box4">
            <pose>1 0 0.25 0 0 0</pose>
            <link name="box_link">
                <inertial>
                <inertia>
                    <ixx>1</ixx>
                    <ixy>0</ixy>
                    <ixz>0</ixz>
                    <iyy>1</iyy>
                    <iyz>0</iyz>
                    <izz>1</izz>
                </inertia>
                <mass>1.0</mass>
                </inertial>
                <collision name="box_collision">
                    <geometry>
                        <box>
                            <size>0.5 0.5 0.5</size>
                        </box>
                    </geometry>
                </collision>
                <visual name="box_visual">
                    <geometry>
                        <box>
                            <size>0.5 0.5 0.5</size>
                        </box>
                    </geometry>
                <material>
                    <ambient>1 0 0 1</ambient>
                    <diffuse>1 0 0 1</diffuse>
                    <specular>1 0 0 1</specular>
                </material>
                </visual>
            </link>
        </model>

    </world>
</sdf>